File: data/all_fiber_data_combined.csv
Fiber_Oz,Specimen_ID,Crosshead (mm),Load (N),Flex Stress (MPa),F Strain (mm/mm)
10-Oz,1,0.00661100466459175,0.222283989191055,0.1749810200727487,9.387626623720285e-05
10-Oz,1,0.161403804668225,19.5168209075928,15.363559217269817,0.0022919340262887943
10-Oz,1,0.314409844577312,37.543815612793,29.554333522884576,0.00446461979299783
10-Oz,1,0.467535021016374,55.8530960083008,43.96732193497512,0.00663899729843251
10-Oz,1,0.620600651018322,73.8530578613281,58.136816093216666,0.008812529244460172
10-Oz,1,0.773547100834548,91.9735336303711,72.40117829856378,0.010984368831850583
10-Oz,1,0.926374457776546,110.173515319824,86.72812722959355,0.013154517300426952
10-Oz,1,1.07938051223755,127.182929992676,100.11786681959993,0.01532720327377321
10-Oz,1,1.23244617134333,144.910354614258,114.07282081712341,0.017500735633075283
10-Oz,1,1.38551171403378,162.996109008789,128.3098505026946,0.019674266339279677
10-Oz,1,1.53857737313956,180.084915161133,141.76208673097508,0.02184779869858175
10-Oz,1,1.69158342760056,196.786651611328,154.90962331998884,0.02402048467192795
10-Oz,1,1.84429169166833,212.620025634766,167.37358866403903,0.026188942021690285
10-Oz,1,1.99729762971401,220.030258178711,173.20689251212366,0.028361626341938936
10-Oz,1,2.15042289346457,234.188079833984,184.35187008906652,0.030536005087196894
10-Oz,1,2.30366713367403,235.383117675781,185.29259884485396,0.032712073298171225
10-Oz,1,2.45661358349025,202.940124511719,159.75361126990353,0.034883912885561544
10-Oz,1,2.6093814522028,51.5579948425293,40.586236387439904,0.03705321662127976
10-Oz,1,2.7623875066638,47.0302391052246,37.022006141091154,0.039225902594625967
10-Oz,1,2.9153935611248,32.1580772399902,25.314702959533573,0.04139858856797216
10-Oz,2,0.125370861496776,17.0406341552734,16.005103930941488,0.0016298211994580881
10-Oz,2,0.278376886853948,37.3635520935059,35.093032867010336,0.003618899529101324
10-Oz,2,0.431204272899777,56.9399261474609,53.47978411520701,0.005605655547697101
10-Oz,2,0.584091176278889,76.7392501831055,72.07593705560768,0.007593185291625557
10-Oz,2,0.737156777177006,96.7570419311523,90.87728179877178,0.009583038103301078
10-Oz,2,0.890401075594127,115.120864868164,108.12516658980371,0.01157521398272365
10-Oz,2,1.04334752541035,133.630447387695,125.50995340255002,0.01356351783033455
10-Oz,2,1.1962940916419,150.851791381836,141.6847857441871,0.015551823191344698
10-Oz,2,1.34918093681335,167.009429931641,156.86055220403966,0.017539352178573553
10-Oz,2,1.5021275030449,181.589477539063,170.5545952278229,0.019527657539583698
10-Oz,2,1.65513355750591,197.098037719727,185.12072670210105,0.021516736247576832
10-Oz,2,1.80825870484114,208.252990722656,195.5978122688607,0.02350736316293482
10-Oz,2,1.96144334040582,200.836700439453,188.6321972757143,0.02549876342527566
10-Oz,2,2.11433041840792,194.534332275391,182.7128132576228,0.02748629543930296
10-Oz,2,2.26721726357937,196.304779052734,184.37567300904857,0.02947382442653181
10-Oz,2,2.42022331804037,142.469039916992,133.81143976424534,0.03146290313452481
10-Oz,2,2.57328897714615,55.3055801391602,51.94475452161191,0.03345275670289995
10-Oz,3,0.111017230665311,11.4869117736816,10.900383915933073,0.001435822849938022
10-Oz,3,0.264023285126314,30.668285369873,29.102346319133087,0.0034147011543003277
10-Oz,3,0.416969764046371,50.5103149414063,47.93123125029066,0.005392808948333065
10-Oz,3,0.570035364944488,70.3535461425781,66.76125645523481,0.007372457386615378
10-Oz,3,0.723160512279719,90.3563766479492,85.74273173856072,0.009352875958817699
10-Oz,3,0.876166566740721,109.845420837402,104.23665491000448,0.011331754263179991
10-Oz,3,1.02899398189038,129.25910949707,122.65907024531035,0.013308322165782246
10-Oz,3,1.18188082706183,146.602722167969,139.11710877879938,0.015285658696666333
10-Oz,3,1.33506557904184,165.425018310547,156.97832841518283,0.017266848155607795
10-Oz,3,1.48825033102185,183.834762573242,174.44806129128074,0.019248037614549258
10-Oz,3,1.64119678083807,202.055191040039,191.73814493725516,0.02122614503217237
10-Oz,3,1.79402413778007,217.321014404297,206.22448719719057,0.023202712181955572
10-Oz,3,1.94697070401162,234.014038085938,222.06515616311322,0.025180821105216952
10-Oz,3,2.0999766420573,250.621826171875,237.8249417084279,0.02715969790394108
10-Oz,3,2.25304230116308,262.046600341797,248.6663607998772,0.0291393470950425
10-Oz,3,2.40610796026886,258.259704589844,245.07282597004766,0.031118996286143917
10-Oz,3,2.55917361937463,257.494079589844,244.34629419196287,0.03309864547724522
10-Oz,3,2.71206046454608,249.569274902344,236.82613426956718,0.035075982008129294
10-Oz,3,2.86506651900709,224.868041992188,213.3861595206983,0.037054860312491694
10-Oz,3,3.01807257346809,200.883895874023,190.62665672876182,0.03903373861685397
10-Oz,3,3.171197604388,96.6581497192383,91.72273290697954,0.04101415568341813
10-Oz,3,3.32408468239009,82.4461669921875,78.23642161777809,0.04299149522557849
10-Oz,3,3.47697152756155,82.9303741455078,78.69590489492184,0.04496883175646272
10-Oz,3,3.62991797737777,80.4515075683594,76.34361057076755,0.04694693917408582
10-Oz,3,3.78298363648355,77.071403503418,73.13609642688041,0.04892658836518725
10-Oz,3,3.93616827204823,52.5722618103027,49.887894009442604,0.050907776318490444
10-Oz,3,4.08923393115401,45.5956535339355,43.26751508238265,0.052887425509591864
10-Oz,3,4.24218038097024,37.6993370056152,35.774388698524966,0.0548655329272151
10-Oz,3,4.39488887786865,37.1800918579102,35.28165648572624,0.05684056282043454
10-Oz,3,4.54795453697443,37.0217819213867,35.13142993921729,0.05882021201153596
10-Oz,3,4.7010793350637,37.2061805725098,35.30641309660755,0.06080062606682386
10-Oz,3,4.85426420345902,36.4476776123047,34.58663970315722,0.06278181703140331
10-Oz,3,5.00715104863048,33.9990539550781,32.263044079261206,0.06475915356228755
10-Oz,3,5.16003789380193,33.9290466308594,32.19661136645329,0.06673649009317163
10-Oz,3,5.31304394826293,33.1583557128906,31.465272338880133,0.0687153683975339
10-Oz,3,5.46599039807916,32.1204872131348,30.480397959718285,0.07069347581515714
10-Oz,3,5.61905605718493,31.3169345855713,29.71787515901502,0.07267312500625843
10-Oz,3,5.77212171629071,30.5350208282471,28.975886336265336,0.07465277419735984
10-Oz,3,5.92518737539649,30.1352062225342,28.596486478119544,0.07663242338846127
10-Oz,3,6.07801461592317,30.9462070465088,29.366077166342254,0.07860898903260632
10-Oz,3,6.23102067038417,31.7813777923584,30.15860364730425,0.08058786733696861
10-Oz,3,6.38408632948995,33.0008964538574,31.31585303381394,0.08256751652807003
10-Oz,3,6.53715198859572,34.18994140625,32.4441847150999,0.0845471657191713
10-Oz,3,6.69015804305673,35.0128593444824,33.22508402335378,0.08652604402353371
10-Oz,3,6.84292567893863,35.6890869140625,33.866783051620885,0.0885018387809396
10-Oz,3,6.99593173339963,36.4869384765625,34.62389588669141,0.09048071708530188
10-Oz,3,7.14911660179496,37.327320098877,35.42136717397951,0.09246190804988148
10-Oz,3,7.30230147019029,38.0514945983887,36.10856493629646,0.09444309901446109
10-Oz,3,7.45524792000651,38.6914672851563,36.71586027545463,0.0964212064320842
10-Oz,3,7.60807516053319,39.702018737793,37.674812430530984,0.09839777207622925
10-Oz,4,0.0343653118761722,4.52730226516724,3.885269286166756,0.0004673682415159419
10-Oz,4,0.187311801710166,25.9274063110352,22.25054778985692,0.0025474405032582578
10-Oz,4,0.340436963597313,46.9650573730469,40.30477406787817,0.004629942704923457
10-Oz,4,0.493681232910603,67.1466674804688,57.62435763070935,0.006714064767584201
10-Oz,4,0.646687287371606,87.0885467529297,74.73820744848281,0.00879494710825384
10-Oz,4,0.799455097876489,106.821632385254,91.6728734014167,0.010872589331120251
10-Oz,4,0.952461152337492,126.352432250977,108.43394045814883,0.01295347167178989
10-Oz,4,1.10540760215372,144.56755065918,124.06590756575423,0.015033543389290591
10-Oz,4,1.25853274948895,163.824234008789,140.591731553102,0.01711604539304972
10-Oz,4,1.41153880394995,182.767135620117,156.84827231637985,0.019196927733719317
10-Oz,4,1.56454485841095,201.290512084961,172.74478229952854,0.021277810074388923
10-Oz,4,1.71737221535295,219.258575439453,188.1647301170678,0.023356262128800123
10-Oz,4,1.87049747910351,234.743957519531,201.45407460002588,0.025438765715807735
10-Oz,4,2.02362262643874,249.995712280273,214.54292329210008,0.027521267719566863
10-Oz,4,2.17656907625496,263.187896728516,225.86427672780042,0.029601339437067452
10-Oz,4,2.32957513071597,252.561004638672,216.7444223364228,0.0316822217777372
10-Oz,4,2.48240260407329,223.419326782227,191.7354303823967,0.03376067541539675
10-Oz,4,2.63540842570364,63.7006530761719,54.66703489400703,0.0358415545895695
10-Oz,5,0.0166168501891661,1.80361473560333,1.547837658252432,0.00022598916257265893
10-Oz,5,0.169801569427364,22.8531284332275,19.612244288964664,0.0023093013442121503
10-Oz,5,0.32292673131451,43.7778625488281,37.56956677791174,0.004391803545877336
10-Oz,5,0.475992332212627,65.0526733398438,55.82732031279505,0.006473495718091728
10-Oz,5,0.628998386673629,84.4078140258789,72.43763904840763,0.008554378058761355
10-Oz,5,0.781885290052742,104.149627685547,89.37979527580997,0.010633639944717293
10-Oz,5,0.934772251639515,123.450828552246,105.9438235914123,0.012712902622297404
10-Oz,5,1.08783785253763,143.268325805664,122.95093045056846,0.014794594794511767
10-Oz,5,1.24096299987286,161.671310424805,138.7441217876409,0.0168770967982709
10-Oz,5,1.39402865897864,181.009429931641,155.3398331785517,0.0189587897621095
10-Oz,5,1.54691550415009,199.486022949219,171.1961942429586,0.021038050856441223
10-Oz,5,1.69980246573687,213.181137084961,182.9491551025713,0.02311731353402143
10-Oz,5,1.85286812484264,224.83674621582,192.95184048015528,0.025199006497859902
10-Oz,5,2.00593378394842,234.580490112305,201.31378909236918,0.027280699461698515
10-Oz,5,2.15893983840942,212.677856445313,182.51724649629352,0.029361581802368107
10-Oz,5,2.31188628822565,167.202407836914,143.49083442916358,0.031441653519868835
10-Oz,5,2.46489234268665,53.6616592407227,46.051706796083494,0.033522535860538445
10-Oz,5,2.61789839714766,49.6783103942871,42.633250942535064,0.03560341820120818
10-Oz,5,2.77090445160866,38.7627754211426,33.265687150840506,0.037684300541877776
10-Oz,5,2.92402948252857,29.909236907959,25.667700702304572,0.03976680096238855
2-Oz,1,0.0452049789601006,0.657030820846558,1.45485687015969,0.00038273548852885174
2-Oz,1,0.198151465156116,2.86008143424988,6.3330501276535625,0.0016776824049884488
2-Oz,1,0.351276627043262,5.10798072814941,11.31055137629073,0.002974142108966285
2-Oz,1,0.504461349919438,7.34373474121094,16.26115944928598,0.0042711060959845755
2-Oz,1,0.657467404380441,9.54015731811523,21.124676310893488,0.005566557357087734
2-Oz,1,0.81017566844821,11.7850694656372,26.095563150751527,0.0068594873261948455
2-Oz,1,0.963122118264437,14.0323219299316,31.07163213096995,0.0081544339346389
2-Oz,1,1.11618777737021,16.2828502655029,36.054954840666106,0.009450389848401112
2-Oz,1,1.26943201757967,18.5483322143555,41.07138918885127,0.010747857748841207
2-Oz,1,1.4223784673959,20.7931480407715,46.04206274583381,0.012042804357285285
2-Oz,1,1.57526542898268,23.048828125,51.03679292180013,0.013337247298720021
2-Oz,1,1.72827148344368,25.2451190948486,55.90001836720148,0.01463269855982316
2-Oz,1,1.88115844503045,27.3984184265137,60.66804785194747,0.01592714150125781
2-Oz,1,2.03422410413623,29.5498580932617,65.43195949899847,0.017223097415020077
2-Oz,1,2.18734913505614,31.6685180664063,70.1232873936173,0.018519556010141984
2-Oz,1,2.34047439880669,32.6816940307617,72.36675294447822,0.01981601657656331
2-Oz,1,2.49330163933337,34.820442199707,77.10256193304652,0.0211099538796892
2-Oz,1,2.64618871733546,36.8476753234863,81.59144425632246,0.02240439780677356
2-Oz,1,2.7992541436106,37.8397941589355,83.78828321420933,0.023700351749236417
2-Oz,1,2.95231980271637,39.8237838745117,88.18141208495722,0.024996307662998596
2-Oz,1,3.10538546182215,41.0525665283203,90.90229340301032,0.026292263576760868
2-Oz,1,3.25821293517947,42.8745956420898,94.93679450964501,0.02758620285118618
2-Oz,1,3.4111593849957,44.6193542480469,98.80019629249645,0.028881149459630263
2-Oz,1,3.56422481127083,45.2650871276855,100.23003624280467,0.03017710340209303
2-Oz,1,3.71740967966616,47.069206237793,104.22487940487188,0.031474068621173495
2-Oz,1,3.87047533877194,48.689395904541,107.81244941352531,0.032770024534935764
2-Oz,1,4.02330281212926,48.8639678955078,108.19900245234359,0.034063963809361074
2-Oz,1,4.17618965730071,50.51220703125,111.84868212370353,0.03535840576514601
2-Oz,1,4.32913610711694,51.9119110107422,114.94803284842344,0.036653352373590097
2-Oz,1,4.48226137086749,52.3754234313965,115.9743838325742,0.037949812940011415
2-Oz,1,4.63538616895676,53.6858406066895,118.8760276668678,0.039246269563833903
2-Oz,1,4.78839222341776,54.2867546081543,120.20662561702146,0.04054172082493703
2-Oz,1,4.9412795342505,55.281665802002,122.40964766658549,0.0418361667233209
2-Oz,1,5.09422598406672,56.3173675537109,124.70299184634354,0.0431311133317649
2-Oz,1,5.24717243388295,52.7763710021973,116.86219808640449,0.04442605994020898
2-Oz,1,5.4002976976335,6.40134239196777,14.174429359644495,0.0457225205066303
2-Oz,1,5.553362891078,6.08887100219727,13.482527041348039,0.047018472477793734
2-Oz,1,5.706368945539,6.10842180252075,13.52581818578946,0.04831392373889687
2-Oz,1,5.85925625637174,6.43189239501953,14.242075930266534,0.049608369637280735
2-Oz,1,6.01220270618796,6.80014991760254,15.057504932558347,0.05090331624572473
2-Oz,1,6.16532750427723,6.56793451309204,14.543312651329105,0.05219977286954722
2-Oz,1,6.31845276802778,6.02281951904297,13.336269893277791,0.05349623343596854
2-Oz,1,6.47128000855446,5.89897394180298,13.062039852357735,0.05479017073909444
2-Oz,2,0.153542074258439,2.10295128822327,3.3380179178147147,0.00153542074258439
2-Oz,2,0.306667236145586,4.42829275131226,7.029036113194065,0.00306667236145586
2-Oz,2,0.459554168628529,6.76808547973633,10.742992824978304,0.00459554168628529
2-Oz,2,0.612381554674357,9.12553977966309,14.484983777243,0.00612381554674357
2-Oz,2,0.765328004490584,11.4919853210449,18.241246541341116,0.00765328004490584
2-Oz,2,0.918453210033476,13.8673048019409,22.011594923715712,0.00918453210033476
2-Oz,2,1.07157835736871,16.2820911407471,25.844589112296983,0.0107157835736871
2-Oz,2,1.22458441182971,18.6326637268066,29.575656709216833,0.0122458441182971
2-Oz,2,1.37747137341648,20.9887981414795,33.31555260552302,0.013774713734164803
2-Oz,2,1.53035821858793,22.493221282959,35.70352584596667,0.015303582185879303
2-Oz,2,1.68342387769371,24.9796829223633,39.650290352957626,0.0168342387769371
2-Oz,2,1.83648942038417,26.3708171844482,41.85843997531461,0.018364894203841697
2-Oz,2,1.98961468413472,29.0001659393311,46.032009427509685,0.0198961468413472
2-Oz,2,2.14262073859572,30.4304466247559,48.30229622977127,0.021426207385957203
2-Oz,2,2.29538837447762,32.8770065307617,52.1857246520027,0.0229538837447762
2-Oz,2,2.44839442893863,35.2120933532715,55.89221167185953,0.0244839442893863
2-Oz,2,2.60151969268918,35.9273643493652,57.027562459309834,0.026015196926891797
2-Oz,2,2.75458535179496,38.2406997680664,60.699523441375234,0.0275458535179496
2-Oz,2,2.90747219696641,40.470874786377,64.2394837879,0.029074721969664104
2-Oz,2,3.06035904213786,41.4131202697754,65.73511153932604,0.030603590421378602
2-Oz,2,3.21336509659886,43.5383148193359,69.10843622116809,0.0321336509659886
2-Oz,2,3.36654996499419,44.6667327880859,70.8995758541046,0.0336654996499419
2-Oz,2,3.51955601945519,46.6434211730957,74.03717646523128,0.035195560194551896
2-Oz,2,3.6725620739162,47.4624710083008,75.33725556873144,0.036725620739162
2-Oz,2,3.82550852373242,49.3698081970215,78.36477491590716,0.038255085237324196
2-Oz,2,3.9783357642591,50.2034912109375,79.6880812872024,0.039783357642591
2-Oz,2,4.1313418187201,51.9049110412598,82.38874768453938,0.041313418187201
2-Oz,2,4.28440747782588,52.5009002685547,83.33476233103923,0.0428440747782588
2-Oz,2,4.43765195086598,54.0667304992676,85.82020714169461,0.044376519508659805
2-Oz,2,4.59059840068221,54.3533782958984,86.27520364428318,0.045905984006822095
2-Oz,2,4.74342564120889,55.775074005127,88.5318635002016,0.04743425641208889
2-Oz,2,4.89643169566989,55.6911888122559,88.3987124004062,0.04896431695669891
2-Oz,2,5.04943775013089,56.9598731994629,90.41249714200461,0.050494377501308904
2-Oz,2,5.20250340923667,58.1452751159668,92.29408748566159,0.05202503409236671
2-Oz,2,5.35550946369767,57.8811187744141,91.87479170541921,0.0535550946369767
2-Oz,2,5.50851551815867,59.051025390625,93.7317863343254,0.055085155181586694
2-Oz,2,5.66134275868535,59.8362350463867,94.97815086728048,0.056613427586853504
2-Oz,2,5.81440841779113,60.6220741271973,96.22551448761477,0.0581440841779113
2-Oz,2,5.96753368154168,59.8996696472168,95.07884070986793,0.0596753368154168
2-Oz,2,6.12059934064746,60.7966995239258,96.5026976570251,0.061205993406474604
2-Oz,2,6.27348618581891,60.1864738464355,95.53408547053255,0.06273486185818909
2-Oz,2,6.42631342634559,11.5852603912354,18.38930220831016,0.0642631342634559
2-Oz,2,6.57937908545136,11.67662525177,18.53432579646032,0.0657937908545136
2-Oz,2,6.73256395384669,12.1504936218262,19.286497812422542,0.0673256395384669
2-Oz,2,6.8855700083077,12.6043329238892,20.00687765696698,0.068855700083077
2-Oz,2,7.0385760627687,13.0483236312866,20.711624811566036,0.070385760627687
2-Oz,2,7.19146290794015,13.3060321807861,21.12068600124778,0.07191462907940151
2-Oz,2,7.3443497531116,13.3910760879517,21.25567633008206,0.073443497531116
2-Oz,2,7.4973558075726,12.4949197769165,19.833205995105555,0.074973558075726
2-Oz,3,0.0536623010702897,0.604929029941559,1.7855048109254985,0.00039352354118212457
2-Oz,3,0.206906581297517,2.47591471672058,7.307894677451534,0.0015173149295151247
2-Oz,3,0.359912635758519,4.32576608657837,12.767904623903098,0.0026393593288958064
2-Oz,3,0.512859085574746,6.16618061065674,18.2000608342879,0.0037609666275481373
2-Oz,3,0.66574604716152,8.03617572784424,23.71952694168902,0.00488213767918448
2-Oz,3,0.818692555185407,9.91145324707031,29.25458455451685,0.006003745404692984
2-Oz,3,0.971698551438749,11.7917785644531,34.80454121739404,0.007125789377217494
2-Oz,3,1.12482369877398,13.7094535827637,40.46473902822815,0.00824870712434252
2-Oz,3,1.27794884610921,15.576681137085,45.97603641406433,0.00937162487146754
2-Oz,3,1.43083580769598,17.424446105957,51.429888152175316,0.010492795923103855
2-Oz,3,1.58372276928276,19.1994190216064,56.668887312887826,0.011613966974740242
2-Oz,3,1.73672882374376,20.9799861907959,61.92439843800442,0.012736011374120906
2-Oz,3,1.88985397107899,22.7537631988525,67.15986776520808,0.013858929121245927
2-Oz,3,2.04291963018477,24.5199871063232,72.37304340709326,0.014981410621354984
2-Oz,3,2.19574687071145,26.2435283660889,77.46023720805461,0.016102143718550635
2-Oz,3,2.34869332052767,27.9197101593018,82.40764509829337,0.017223751017202915
2-Oz,3,2.50175897963345,29.6030941009521,87.37631080564374,0.018346232517311968
2-Oz,3,2.654884243384,29.961389541626,88.43385342864816,0.019469151118149338
2-Oz,3,2.80794990248978,31.7121410369873,93.60136079394125,0.020591632618258388
2-Oz,3,2.96089635230601,33.4268341064453,98.66243833071219,0.021713239916910744
2-Oz,3,3.11366398818791,34.1474151611328,100.78930094785358,0.02283353591337801
2-Oz,3,3.26667004264891,35.7492294311523,105.5172061132004,0.023955580312758677
2-Oz,3,3.41973570175469,37.3058166503906,110.11161939312453,0.025078061812867734
2-Oz,3,3.57292057015002,38.7648849487305,114.41819642482436,0.026201417514433483
2-Oz,3,3.72592662461102,38.9283599853516,114.90070833929043,0.02732346191381415
2-Oz,3,3.8787538651377,40.4863166809082,119.49916375710802,0.0284441950110098
2-Oz,3,4.03176015242934,41.8485450744629,123.51990872037454,0.02956624111781516
2-Oz,3,4.18470660224557,42.1669654846191,124.45975644810831,0.03068784841646752
2-Oz,3,4.33777179569006,43.4995536804199,128.39301558565495,0.03181032650172711
2-Oz,3,4.49083745479584,44.8114242553711,132.2651247206939,0.032932808001836164
2-Oz,3,4.64396271854639,44.7962226867676,132.22025586413102,0.034055726602673524
2-Oz,3,4.79673082008958,45.2186660766602,133.46713718022488,0.03517602601399026
2-Oz,3,4.94967726990581,46.3666000366211,136.85537200891704,0.036297633312642616
2-Oz,3,5.10280206799507,46.0043449401855,135.78614209027594,0.03742054849863052
2-Oz,3,5.25592733174562,47.1567344665527,139.1875279414188,0.03854346709946788
2-Oz,3,5.40881417691708,45.9748344421387,135.69903908541528,0.039664637297391926
2-Oz,3,5.56164188310504,46.636775970459,137.65282163653777,0.040785373809436955
2-Oz,3,5.71470754221082,19.8860874176025,58.69565353483618,0.041907855309546015
2-Oz,4,0.141511234687641,1.90333580970764,6.284789101158468,0.0009811445605009776
2-Oz,4,0.294755504000932,3.85444784164429,12.727334641946753,0.0020436381610731283
2-Oz,4,0.44770201202482,5.76361131668091,19.03136661520271,0.003104067283372085
2-Oz,4,0.600648461841047,7.6563892364502,25.281293706579536,0.004164496002097926
2-Oz,4,0.753594969864935,9.54051399230957,31.502648167759304,0.005224925124396883
2-Oz,4,0.906481931451708,11.39621925354,37.63016184204618,0.006284941391398509
2-Oz,4,1.05954753234982,13.2426862716675,43.72717096255382,0.007346196224292086
2-Oz,4,1.21261307504028,15.0942354202271,49.840961209012775,0.008407450653612607
2-Oz,4,1.36573822237551,16.9314613342285,55.907456328681384,0.009469118341803535
2-Oz,4,1.51862518396229,18.7395210266113,61.877644979036674,0.010529134608805212
2-Oz,4,1.67151214554906,20.526065826416,67.77679174508664,0.011589150875806817
2-Oz,4,1.82457768823951,22.3063659667969,73.65531873017783,0.01265040530512727
2-Oz,4,1.97764323092997,24.0534782409668,79.42425982990412,0.013711659734447794
2-Oz,4,2.13070889003575,25.7568187713623,85.04866722369736,0.014772914970914531
2-Oz,4,2.28353636339307,27.4471073150635,90.62997713395333,0.015832518786191956
2-Oz,4,2.43654241785407,29.0176372528076,95.8158457470665,0.01689336076378822
2-Oz,4,2.58954847231507,30.5316944122314,100.8152420099568,0.017954202741384487
2-Oz,4,2.74273310787976,32.0709037780762,105.89769051826725,0.01901628288129967
2-Oz,4,2.89579876698554,33.5269241333008,110.70545003863587,0.020077538117766414
2-Oz,4,3.04868561215699,35.0433464050293,115.71265587036828,0.021137553577621794
2-Oz,4,3.20157269015908,36.5140266418457,120.56882212147909,0.02219757065176962
2-Oz,4,3.35445953533053,38.1887283325195,126.09866445384978,0.023257586111625008
2-Oz,4,3.50758479908109,39.8945388793945,131.73122780865154,0.024319254606962222
2-Oz,4,3.660709830001,41.3780822753906,136.62986803740026,0.025380921488006934
2-Oz,4,3.813715884462,42.8373832702637,141.4484601855178,0.026441763465603202
2-Oz,4,3.96660296246409,44.380786895752,146.544758082444,0.027501780539751025
2-Oz,4,4.11954941228032,45.6699371337891,150.80151473276726,0.028562209258476884
2-Oz,4,4.27249586209655,46.2813568115234,152.82041423923351,0.029622637977202746
2-Oz,4,4.4256211258471,43.8416748046875,144.76461724920586,0.030684306472539894
2-Oz,4,4.57868678495288,44.9552459716797,148.4416141816347,0.03174556170900664
2-Oz,4,4.73175197839737,38.5444107055664,127.27312283906907,0.032806813716888435
2-Oz,4,4.88457968458533,24.0693588256836,79.47669730585508,0.03386641914645829
2-Oz,5,0.113280460936949,1.16670989990234,3.8524603098000973,0.0007854111958295132
2-Oz,5,0.266107817878947,2.60487771034241,8.601270968744748,0.0018450142039606993
2-Oz,5,0.419173447880894,4.02590179443359,13.293473275153177,0.0029062692386408653
2-Oz,5,0.57235814165324,5.4311056137085,17.93343728110636,0.00396834978212913
2-Oz,5,0.725483347196132,6.84322166442871,22.596225381804434,0.005030017873893181
2-Oz,5,0.878429797012359,8.26675415039063,27.29671039726407,0.006090446592619023
2-Oz,5,1.03125721216202,9.67925930023193,31.96078329799744,0.007150050004323339
2-Oz,5,1.18414405733347,11.0877676010132,36.611658657191725,0.008210065464178726
2-Oz,5,1.33720971643925,12.4942436218262,41.255823455417236,0.009271320700645468
2-Oz,5,1.4902752591297,13.8599100112915,45.765235402880315,0.010332575129965922
2-Oz,5,1.64340052288026,15.2461633682251,50.3426252384863,0.011394243625303137
2-Oz,5,1.79634697269648,16.6192531585693,54.87654915525049,0.01245467234402893
2-Oz,5,1.94923393428326,17.9450855255127,59.254429699098885,0.013514688611030605
2-Oz,5,2.10229959338903,19.2432861328125,63.54107054632191,0.014575943847497275
2-Oz,5,2.25530564785004,20.5074901580811,67.71545513947954,0.015636785825093612
2-Oz,5,2.40837107412517,21.7726345062256,71.89294466605557,0.016698039447267846
2-Oz,5,2.5613175239414,22.9915447235107,75.91776971784756,0.017758468165993708
2-Oz,5,2.7143235784024,24.1837978363037,79.85457337114228,0.018819310143589972
2-Oz,5,2.86715105175972,25.3833293914795,83.81541034274454,0.01987891395886739
2-Oz,5,3.0202167108655,26.5245037078857,87.58355250120754,0.020940169195334132
2-Oz,5,3.17340134643018,27.5650405883789,91.01939120740072,0.02200224933524925
2-Oz,5,3.32640740089118,28.5895671844482,94.4023641709643,0.023063091312845518
2-Oz,5,3.4792348742485,29.6450672149658,97.88761099616242,0.024122695128122935
2-Oz,5,3.63206211477518,30.6328086853027,101.14911997207408,0.025182297329107914
2-Oz,5,3.78524698317051,31.777099609375,104.92755312689863,0.026244379083315537
2-Oz,5,3.93843138590455,33.2125587463379,109.66741978265631,0.02730645760893821
2-Oz,5,4.09143744036555,32.4993133544922,107.31229314538052,0.028367299586534483
2-Oz,5,4.24432475119829,33.7505989074707,111.44402111775776,0.02942731827497481
2-Oz,5,4.39721159636974,34.9115180969238,115.27736057997343,0.0304873337348302
2-Oz,5,4.55015804618597,36.0280838012695,118.96424543424259,0.03154776245355606
2-Oz,5,4.70322370529175,37.1601943969727,122.7024593095305,0.0326090176900228
2-Oz,5,4.85628936439753,38.3660354614258,126.68413019543071,0.033670272926489546
2-Oz,5,5.00941416248679,35.6260833740234,117.63684546050624,0.034731938193241746
2-Oz,5,5.16230147331953,39.6564712524414,130.94513172430194,0.03579195688168207
2-Oz,5,5.31524792313576,40.644718170166,134.20830968065167,0.03685238560040793
2-Oz,5,5.46825397759676,41.6935424804688,137.6715133679892,0.0379132275780042
2-Oz,5,5.62137877568603,41.4283866882324,136.7959725282399,0.03897489284475648
2-Oz,5,5.77432569116354,42.1190605163574,139.07656816738893,0.04003532479206721
2-Oz,5,5.92727214097977,41.4356689453125,136.82001844262632,0.04109575351079307
2-Oz,5,6.08015898615122,42.9857902526855,141.93849803427958,0.04215576897064846
2-Oz,5,6.23316504061222,38.0899848937988,125.77261495469277,0.04321661094824472
4-Oz,1,0.14168991765473,3.20048189163208,5.6686631968431715,0.0013413312204647772
4-Oz,1,0.294755504000932,6.73291015625,11.925266663803242,0.002790352104542156
4-Oz,1,0.447642436483875,10.3199253082275,18.27855390835772,0.00423768173204735
4-Oz,1,0.600529368966818,13.9379549026489,24.686773639458053,0.005685011359552543
4-Oz,1,0.753594969864935,17.5396308898926,31.06602801650147,0.007134032381388051
4-Oz,1,0.906720117200166,21.0886154174805,37.35195577953726,0.008583617109494904
4-Oz,1,1.05972622986883,24.5608425140381,43.50193150812994,0.01003207497609159
4-Oz,1,1.21249398216605,26.6706638336182,47.23882703548439,0.011478276364505274
4-Oz,1,1.36550003662705,30.3754558563232,53.80071955734974,0.012926733680069406
4-Oz,1,1.51856569573283,32.6046485900879,57.749044602275454,0.014375755252937456
4-Oz,1,1.67175033129752,36.2511138916016,64.20762938830448,0.01582590313628319
4-Oz,1,1.82481599040329,38.9139595031738,68.92403630085761,0.017274924709151145
4-Oz,1,1.97764323092997,41.2177886962891,73.0045567352869,0.018721689252803715
4-Oz,1,2.13053030893207,44.6109886169434,79.01456027882683,0.020169020257890264
4-Oz,1,2.28353636339307,46.686840057373,82.69128867814811,0.021617477573454395
4-Oz,1,2.43660202249885,49.933422088623,88.44160400541098,0.023066499146322448
4-Oz,1,2.58972705341876,52.0919456481934,92.26476047870568,0.024516082772364257
4-Oz,1,2.74267350323498,54.4545860290527,96.44944673153834,0.025963975830624476
4-Oz,1,2.89556058123708,56.4333038330078,99.95413295443045,0.02741130683571102
4-Oz,1,3.04856663569808,58.5960083007813,103.78469461271379,0.02885976415127516
4-Oz,1,3.20157269015908,61.5381851196289,108.9958503124892,0.03030822146683929
4-Oz,1,3.35463811643422,63.8085174560547,113.01704143178563,0.03175724083557728
4-Oz,1,3.50770377553999,65.6138534545898,116.21463544398398,0.03320626240844523
4-Oz,1,3.660709830001,67.1914901733398,119.00893064963691,0.034654719724009464
4-Oz,1,3.81353730335832,69.7953109741211,123.6207933766704,0.036101486471792094
4-Oz,1,3.96654335781932,70.3831100463867,124.66189752314362,0.037549943787356224
4-Oz,1,4.1196090169251,72.7951583862305,128.93409468471125,0.03899896536022428
4-Oz,1,4.27279341965914,72.4889755249023,128.39178650229246,0.040449111039439864
4-Oz,1,4.4256211258471,75.1672592163086,133.13553719554758,0.041895879991352546
4-Oz,2,0.0734357527107932,1.76864576339722,3.4151124633071617,0.000665817491244525
4-Oz,2,0.226560921873897,5.66869163513184,10.945786801647923,0.0020541523583233333
4-Oz,2,0.379626522772014,9.49757480621338,18.339051698848746,0.003441947139799594
4-Oz,2,0.53281121654436,13.3423557281494,25.763013872013634,0.004830821696668865
4-Oz,2,0.685638631694019,17.1793632507324,33.17196623735711,0.006216456927359106
4-Oz,2,0.838525535073131,21.0258884429932,40.599296455977345,0.007602631517996388
4-Oz,2,0.991591135971248,24.8499374389648,47.983226950546836,0.008990426299472649
4-Oz,2,1.14459719043225,28.6181373596191,55.259317380628815,0.0103776811932524
4-Oz,2,1.29766284953803,32.3056983947754,62.37970062016381,0.011765476502478141
4-Oz,2,1.45049020648003,36.0518226623535,69.6131647428662,0.01315111120541894
4-Oz,2,1.60349626094103,37.8169174194336,73.02142049909169,0.01453836609919867
4-Oz,2,1.75656180363148,41.8201484680176,80.75133709994746,0.01592616035292542
4-Oz,2,1.90968695096672,45.0136413574219,86.91771455878857,0.017314495022098263
4-Oz,2,2.06275261007249,48.0139503479004,92.71106947428864,0.01870229033132391
4-Oz,2,2.21569905988872,51.0958709716797,98.6620098779653,0.02008900480965773
4-Oz,2,2.36852653324604,53.5688438415527,103.43712123384338,0.02147464056809743
4-Oz,2,2.52147298306227,56.1760711669922,108.47146712608169,0.02286135504643125
4-Oz,2,2.67459801398218,59.1594924926758,114.23221332155947,0.024249688660105097
4-Oz,2,2.82766367308795,61.54345703125,118.83545676140399,0.025637483969330747
4-Oz,2,2.98072933219373,64.8208465576172,125.16383186638268,0.027025279278556486
4-Oz,2,3.13361617736518,65.2199935913086,125.93455262780482,0.028411453341444296
4-Oz,2,3.28656262718141,67.9243927001953,131.1565294044181,0.029798167819778117
4-Oz,2,3.43950930982828,59.0497550964355,114.0203192513352,0.031184884409109742
4-Oz,2,3.59257473610342,45.0527381896973,86.99320739174743,0.032572677607337674
4-Oz,3,0.0820121931610629,1.99400281906128,4.784626874163243,0.0006670325043766449
4-Oz,3,0.235137355048209,5.79494762420654,13.905026548658531,0.0019124504877254332
4-Oz,3,0.388322077924386,9.47441387176514,22.73393738186053,0.0031583529004516725
4-Oz,3,0.541268556844443,13.1670989990234,31.594567030328346,0.004402317595668136
4-Oz,3,0.693976820912212,16.8404331207275,40.4087637749249,0.005644344810085991
4-Oz,3,0.846982875373214,20.5358829498291,49.27602734918873,0.006888794053035474
4-Oz,3,1.00010808091611,24.1967926025391,58.060411473824004,0.008134212391451028
4-Oz,3,1.15329271648079,27.7276992797852,66.53285234332456,0.009380114094043759
4-Oz,3,1.30623928271234,31.2792110443115,75.05473529655886,0.010624079499393698
4-Oz,3,1.45912612788379,34.7124137878418,83.29273473874582,0.011867559173454823
4-Oz,3,1.61207269411534,38.1014137268066,91.4246691720894,0.013111524578804766
4-Oz,3,1.76501914393157,40.1741638183594,96.39825080229826,0.014355489037310104
4-Oz,3,1.91808468662202,43.6329917907715,104.69773820106803,0.015600422117859095
4-Oz,3,2.07120995037258,46.2005081176758,110.85851565841507,0.01684584092969698
4-Oz,3,2.22427560947835,49.0859146118164,117.78207329974757,0.01809077495709058
4-Oz,3,2.37710285000503,51.3268585205078,123.15923743739152,0.01933376984670758
4-Oz,3,2.53004929982126,53.8596954345703,129.23680134605303,0.020577734305212914
4-Oz,3,2.68317456357181,56.2768478393555,135.03677928205624,0.021823153117050714
4-Oz,3,2.83618061803281,58.4999694824219,140.37117874040655,0.02306760236000019
4-Oz,3,2.98924627713859,60.739688873291,145.7454046370287,0.02431253638739386
4-Oz,3,3.14201391302049,62.7025871276855,150.45539584137688,0.02555504649256665
4-Oz,3,3.29501996748149,63.7016983032227,152.85277168009438,0.026799495735516116
4-Oz,3,3.44808562658727,66.4891586303711,159.54130665328802,0.028044429762909794
4-Oz,3,3.60127026215196,44.4471092224121,106.65121996394042,0.029290331465502608
4-Oz,4,0.0962467020144686,2.15968608856201,5.3563643069494296,0.0007699736161157488
4-Oz,4,0.249133619945496,5.47629022598267,13.582069012853845,0.001993068959563968
4-Oz,4,0.402258796384558,8.82312297821045,21.882745481672742,0.0032180703710764642
4-Oz,4,0.555324368178844,12.2355260848999,30.34604683754936,0.004442594945430751
4-Oz,4,0.708330422639847,15.5513353347778,38.5697800961751,0.005666643381118776
4-Oz,4,0.861157837789506,17.6427593231201,43.75684355932564,0.0068892627023160475
4-Oz,4,1.01416383404285,21.1535377502441,52.46413132501018,0.008113310672342802
4-Oz,4,1.16722949314862,23.4220790863037,58.090473924364346,0.00933783594518896
4-Oz,4,1.32035464048386,26.0107383728027,64.51075985318128,0.010562837123870879
4-Oz,4,1.47347978781909,29.473123550415,73.09802467860864,0.011787838302552717
4-Oz,4,1.62630714476109,31.7406959533691,78.72196417006226,0.013010457158088719
4-Oz,4,1.77919410634786,35.0976028442383,87.0476261017815,0.014233552850782882
4-Oz,4,1.93214055616409,37.3344917297363,92.5954655995444,0.01545712444931272
4-Oz,4,2.08526570349932,40.6552658081055,100.83151242089659,0.016682125627994558
4-Oz,4,2.23839096724987,42.3747253417969,105.09604499453599,0.01790712773799896
4-Oz,4,2.39139702171087,45.6624145507813,113.25003608824728,0.019131176173686957
4-Oz,4,2.54422426223755,47.640380859375,118.15570649646578,0.020353794097900398
4-Oz,4,2.69723031669855,50.7425346374512,125.84954027145636,0.0215778425335884
4-Oz,4,2.85017676651478,52.5927352905273,130.43833157372845,0.022801414132118236
4-Oz,4,3.00330203026533,54.6640930175781,135.5756275237552,0.02402641624212264
4-Oz,4,3.15636768937111,56.9543724060059,141.25588394346704,0.02525094151496888
4-Oz,4,3.30937374383211,58.9153137207031,146.1193296644422,0.02647498995065688
4-Oz,4,3.46220098435879,61.5601348876953,152.67890597146652,0.02769760787487032
4-Oz,4,3.61520703881979,63.3744354248047,157.1786592877101,0.02892165631055832
4-Oz,4,3.76833230257034,64.6572036743164,160.36012816050697,0.03014665842056272
4-Oz,4,3.92139796167612,66.915657043457,165.96145100063742,0.03137118369340895
4-Oz,4,4.07428480684757,69.0986022949219,171.37550172351663,0.03259427845478056
4-Oz,4,4.22711204737425,71.3562850952148,176.9749134305923,0.033816896378994
4-Oz,4,4.38017770648003,73.0803833007813,181.25095064677907,0.03504142165184024
4-Oz,4,4.53330297023058,75.6093139648438,187.52310011121978,0.03626642376184464
4-Oz,4,4.68636862933636,78.1957092285156,193.93777090405655,0.03749094903469087
4-Oz,4,4.83937468379736,19.1522083282471,47.500516687120786,0.03871499747037888
4-Oz,4,4.99232113361359,9.74692630767822,24.17392437420194,0.03993856906890871
4-Oz,4,5.14514837414026,8.87781238555908,22.018383892755654,0.04116118699312208
4-Oz,4,5.29815442860126,8.49224948883057,21.062126708409153,0.04238523542881007
4-Oz,5,0.113220899947919,2.24195146560669,5.560395500016593,0.0009057671995833518
4-Oz,5,0.266226939857006,5.4032039642334,13.400803482721729,0.0021298155188560477
4-Oz,5,0.419232994318008,8.5279426574707,21.150651432219,0.003353863954544064
4-Oz,5,0.57235814165324,11.6657609939575,28.93293897310888,0.0045788651332259196
4-Oz,5,0.725304649677128,14.7626647949219,36.61375197153249,0.005802437197417023
4-Oz,5,0.878370250575244,17.8873023986816,44.36334920307937,0.007026962004601951
4-Oz,5,1.03119760751724,20.9805812835693,52.03517183424926,0.00824958086013792
4-Oz,5,1.18420366197824,24.0393543243408,59.62141449489286,0.009473629295825918
4-Oz,5,1.33738841395825,27.0735130310059,67.14660969991543,0.010699107311666
4-Oz,5,1.49039446841925,30.0690727233887,74.57607322269024,0.011923155747354
4-Oz,5,1.64322182536125,33.0217018127441,81.89906203557565,0.01314577460289
4-Oz,5,1.79610878694803,35.9025192260742,89.04394649323959,0.01436887029558424
4-Oz,5,1.94917432963848,38.7246856689453,96.04336723448735,0.015593394637107839
4-Oz,5,2.10235896520317,41.3105392456055,102.45669455755333,0.01681887172162536
4-Oz,5,2.25542462430894,44.0460739135742,109.24125474596777,0.018043396994471522
4-Oz,5,2.40837107412517,46.8506393432617,116.19702218070859,0.01926696859300136
4-Oz,5,2.56125815212727,50.1639175415039,124.41447802952356,0.02049006521701816
4-Oz,5,2.71414499729872,53.2537460327148,132.07774313669347,0.02171315997838976
4-Oz,5,2.8672106564045,56.2797889709473,139.582809947786,0.022937685251235997
4-Oz,5,3.02027631551027,59.2462425231934,146.9400856229995,0.02416221052408216
4-Oz,5,3.17340134643018,62.4008979797363,154.76413189418727,0.02538721077144144
4-Oz,5,3.32634779624641,65.4166107177734,162.24357816908085,0.02661078236997128
4-Oz,5,3.4792348742485,68.4981994628906,169.88640739804217,0.027833878993988
4-Oz,5,3.63224092870951,71.4026336669922,177.0898652455164,0.02905792742967608
4-Oz,5,3.78530635498464,74.351188659668,184.40274965195437,0.030282450839877118
4-Oz,5,3.93831264227629,76.8798599243164,190.67425576467363,0.03150650113821032
4-Oz,5,4.09131869673729,79.4744186401367,197.10917321462478,0.03273054957389832
4-Oz,5,4.24420554190874,82.1538238525391,203.7545234437974,0.033953644335269914
4-Oz,5,4.39721159636974,84.427848815918,209.39446630932045,0.03517769277095791
4-Oz,5,4.55027725547552,9.1409215927124,22.670936489862104,0.03640221804380416
6-Oz,1,0.153006039909087,6.44720411300659,13.417475074310081,0.0013362527485393598
6-Oz,1,0.306012079818174,12.7756643295288,26.587828567950577,0.0026725054970787197
6-Oz,1,0.458958587842062,19.0371150970459,39.61872663315886,0.004008238333820675
6-Oz,1,0.611785973887891,25.3618602752686,52.78134864615906,0.005342930838620915
6-Oz,1,0.764851574786007,31.6190948486328,65.80347225984332,0.006679703753131127
6-Oz,1,0.917917175684124,38.1120681762695,79.31619905655992,0.00801647666764135
6-Oz,1,1.07098277658224,44.523006439209,92.65820015318995,0.009353249582151562
6-Oz,1,1.22410792391747,49.7792854309082,103.59720427320293,0.010690542535545905
6-Oz,1,1.37693528085947,56.5685768127441,117.72660770006762,0.012025234786172704
6-Oz,1,1.52982224244624,62.1739158630371,129.39205146019856,0.013360447584030495
6-Oz,1,1.68276869226247,67.6051788330078,140.69522012746464,0.014696179912425575
6-Oz,1,1.83595344424248,73.5338516235352,153.03356369412202,0.016033993413050993
6-Oz,1,1.98913807980716,79.4331817626953,165.31084136517038,0.01737180589698253
6-Oz,1,2.14202515780926,85.1494064331055,177.20705260496285,0.018707019711534205
6-Oz,1,2.29485239833593,90.1308517456055,187.57409188942847,0.020041710945467122
6-Oz,1,2.44785845279694,95.7435760498047,199.2549053289533,0.021377963821093277
6-Oz,1,2.60092411190271,100.340179443359,208.8210382415256,0.02271473724395033
6-Oz,1,2.75398977100849,105.63158416748,219.83314360526774,0.024051510666807486
6-Oz,1,2.90693622082472,110.825759887695,230.6429026940134,0.025387242995202553
6-Oz,1,3.05994227528572,115.108558654785,239.55596713225373,0.02672349587082862
6-Oz,1,3.21288872510195,119.70467376709,249.12108386767753,0.028059228199223702
6-Oz,1,3.36589477956295,125.036933898926,260.21821467889396,0.029395481074849763
6-Oz,1,3.51896043866873,129.081741333008,268.63598802310884,0.030732254497706914
6-Oz,1,3.67208546958864,132.800537109375,276.3752884642399,0.03206954643440746
6-Oz,1,3.82485333830118,138.072219848633,287.3463497977827,0.03340371915449697
6-Oz,1,3.97779978811741,143.331649780273,298.2919114359657,0.03473945148289205
6-Oz,1,4.13074623793364,148.13069152832,308.2793450438286,0.036075183811287125
6-Oz,1,4.28399071097374,152.975479125977,318.3619817484349,0.037413518875837326
6-Oz,1,4.43705637007952,154.369155883789,321.26240537886775,0.03875029229869448
6-Oz,2,0.025371964511578,1.14176332950592,1.8367308575320287,0.0002520281808150081
6-Oz,2,0.178378017153591,9.52846145629883,15.328237235611702,0.0017718883037256706
6-Oz,2,0.331443618051708,17.5847988128662,28.28829913206323,0.0032923399393136334
6-Oz,2,0.48444967251271,25.6644344329834,41.28584045921902,0.004812200080292918
6-Oz,2,0.637515273410827,33.6938133239746,54.20253483429736,0.006332651715880881
6-Oz,2,0.790402176789939,41.6030578613281,66.92597157999333,0.007851328289446726
6-Oz,2,0.943467777688056,49.5231819152832,79.66690997716191,0.009371779925034688
6-Oz,2,1.09635468106717,57.2315368652344,92.0671798330101,0.010890456498600556
6-Oz,2,1.24942034017295,63.3006591796875,101.83045033313735,0.012410908712384637
6-Oz,2,1.40254548750818,71.3562316894531,114.78928183648918,0.013931951842581256
6-Oz,2,1.55555154196918,78.1555938720703,125.72727398391046,0.015451811983560522
6-Oz,2,1.70837889891118,85.105598449707,136.907601410662,0.01696989706251772
6-Oz,2,1.86126586049795,91.0493087768555,146.46912426218816,0.018488574214279636
6-Oz,2,2.01439089141786,97.6681289672852,157.11668227184938,0.020009616188084077
6-Oz,2,2.16763536445796,104.201751708984,167.62718492246808,0.021531844620282403
6-Oz,2,2.32058181427419,110.128753662109,177.16182936114362,0.023051112688456953
6-Oz,2,2.47346865944564,116.319755554199,187.12116499610542,0.02456978868382669
6-Oz,2,2.62635573744774,121.098739624023,194.80901700699292,0.026088466991980884
6-Oz,2,2.7793615590781,126.271766662598,203.13075772423056,0.027608324820175792
6-Oz,2,2.9323676135391,130.979110717773,210.7033639375527,0.02912818496115506
6-Oz,2,3.08543327264488,137.082504272461,220.521765867144,0.03064863717493914
6-Oz,2,3.23855853639543,140.777282714844,226.46547889548737,0.03216968146152793
6-Oz,2,3.39144538156688,145.839202880859,234.60848430389075,0.033688357456897675
6-Oz,2,3.54439183138311,124.290100097656,199.94289204742384,0.03520762552507223
6-Oz,3,0.121737779409159,6.34467935562134,10.070919612097367,0.0012173777940915902
6-Oz,3,0.274684280157089,14.3696527481079,22.808972616044286,0.00274684280157089
6-Oz,3,0.427809427492321,22.3182697296143,35.42582496764175,0.00427809427492321
6-Oz,3,0.580875028390437,30.2238121032715,47.97430492582778,0.005808750283904371
6-Oz,3,0.733821536414325,38.0185089111328,60.346839541480634,0.00733821536414325
6-Oz,3,0.886648893356323,45.9431228637695,72.92559184725319,0.008866488933563229
6-Oz,3,1.03965494781733,53.9272079467773,85.59874277266239,0.0103965494781733
6-Oz,3,1.19278009515256,61.9512100219727,98.33525400313127,0.0119278009515256
6-Oz,3,1.34596484713256,68.316520690918,108.43892173161588,0.013459648471325601
6-Oz,3,1.49891129694879,75.6334228515625,120.0530521453373,0.0149891129694879
6-Oz,3,1.65179825853556,83.0488815307617,131.82362147739954,0.016517982585355598
6-Oz,3,1.80468522012234,90.5377731323242,143.7107510036892,0.0180468522012234
6-Oz,3,1.95769127458334,97.8058700561523,155.24741278754334,0.0195769127458334
6-Oz,3,2.11075693368912,105.022613525391,166.7025611514143,0.021107569336891202
6-Oz,3,2.26388196460903,110.641098022461,175.62079051184287,0.0226388196460903
6-Oz,3,2.41688801907003,117.830528259277,187.03258453853493,0.0241688801907003
6-Oz,3,2.56971549242735,124.45329284668,197.54490928044444,0.025697154924273498
6-Oz,3,2.72272154688835,130.759414672852,207.55462646484443,0.027227215468883504
6-Oz,3,2.87572760134935,135.722122192383,215.43193998790954,0.0287572760134935
6-Oz,3,3.02879302762449,142.613861083984,226.37120806981588,0.030287930276244903
6-Oz,3,3.18179908208549,147.203796386719,233.65681966145877,0.031817990820854895
6-Oz,3,3.33480513654649,151.220855712891,240.03310430617623,0.033348051365464905
6-Oz,3,3.48769221454859,157.862686157227,250.57569231305874,0.0348769221454859
6-Oz,3,3.64069826900959,161.806259155273,256.8353319924969,0.0364069826900959
6-Oz,3,3.79388290457428,167.313461303711,265.5769227043032,0.0379388290457428
6-Oz,3,3.94694833084941,171.055511474609,271.51668488033175,0.039469483308494105
6-Oz,3,4.0997164323926,173.588745117188,275.53769066220326,0.04099716432392599
6-Oz,3,4.25260327756405,177.184860229492,281.2458098880826,0.0425260327756405
6-Oz,3,4.40566893666983,33.5402145385742,53.2384357755146,0.0440566893666983
6-Oz,3,4.55891294404864,33.1224555969238,52.57532634432349,0.045589129440486396
6-Oz,3,4.71197860315442,30.5950508117676,48.56357271709143,0.047119786031544195
6-Oz,3,4.86486544832587,29.0718593597412,46.14580850752572,0.0486486544832587
6-Oz,4,0.0934474446694367,4.39909553527832,8.881822309422159,0.0008285673427356721
6-Oz,4,0.246334384428337,11.759313583374,23.742183567216912,0.002184164875264588
6-Oz,4,0.399399985326454,19.0699043273926,38.50234675180015,0.0035413465365612255
6-Oz,4,0.552406010683626,26.3542613983154,53.20954386163192,0.004897999961394819
6-Oz,4,0.705471611581743,33.6540107727051,67.94781820159642,0.006255181622691455
6-Oz,4,0.85853721247986,40.9734649658203,82.72587678747142,0.007612363283988092
6-Oz,4,1.01148372050375,48.2867889404297,97.49155839470394,0.008968488988466583
6-Oz,4,1.16437068209052,54.6336097717285,110.3058595166659,0.010324086714535944
6-Oz,4,1.31737673655152,61.4472846984863,124.06274419632518,0.011680740397423478
6-Oz,4,1.47056137211621,68.9472427368164,139.20524203261186,0.013038977499430398
6-Oz,4,1.62356742657721,75.5211944580078,152.47812292144388,0.014395631182317929
6-Oz,4,1.77645438816398,82.1933822631836,165.94934354518867,0.015751228908387288
6-Oz,4,1.92928174510598,88.0412902832031,177.75633420932112,0.01710629813993969
6-Oz,4,2.08228779956698,94.3934860229492,190.58148733060335,0.018462951822827225
6-Oz,4,2.23553203977644,100.826377868652,203.56956677808645,0.0198217174193511
6-Oz,4,2.388657303527,107.395172119141,216.83203467679874,0.021179428091272736
6-Oz,4,2.54160375334322,113.229194641113,228.6109903675266,0.022535553279643218
6-Oz,4,2.6944309938699,118.790405273438,239.83913585003992,0.023890621478979777
6-Oz,4,2.847318071872,124.705596923828,251.78197290452496,0.02524622023726507
6-Oz,4,3.00038373097777,130.258987426758,262.9943294597086,0.02660340241466956
6-Oz,4,3.15344915725291,136.047943115234,274.6822947175282,0.027960582527642473
6-Oz,4,3.30657442100346,141.520034790039,285.7305080438186,0.029318293199564013
6-Oz,4,3.45946126617491,146.346374511719,295.47494106853935,0.030673889893417537
6-Oz,4,3.61240771599114,150.558242797852,303.97874950100544,0.03203001508178811
6-Oz,4,3.76547337509692,153.676834106445,310.27521968141014,0.03338719725919269
6-Oz,4,3.91842005774379,151.122283935547,305.11755476677797,0.03474332451199494
6-Oz,4,4.07154485583305,24.5793075561523,49.62589251623749,0.036101031055053044
6-Oz,4,4.22443216666579,21.6628723144531,43.737577660154216,0.037456631877770014
6-Oz,4,4.37743822112679,21.8216361999512,44.05812369259184,0.038813285560657544
6-Oz,4,4.53032506629825,21.7120952606201,43.83695933029424,0.04016888225451115
6-Oz,4,4.6834503300488,18.9882164001465,38.33741792749832,0.0415265929264327
6-Oz,5,0.0708747320459224,2.90407204627991,5.8633534284420294,0.000628422624140512
6-Oz,5,0.223761657252908,9.2390604019165,18.653764651794294,0.0019840200276424512
6-Oz,5,0.376648589735851,15.6742010116577,31.646384378624525,0.003339617495657879
6-Oz,5,0.529654615093023,22.1294574737549,44.67961823278975,0.004696270920491471
6-Oz,5,0.682660669554025,27.8387546539307,56.20675208549846,0.006052924603379023
6-Oz,5,0.835785875096917,33.7892646789551,68.22089732714257,0.007410634759192665
6-Oz,5,0.988911022432148,39.5800247192383,79.91250559112261,0.008768344398898379
6-Oz,5,1.14179798401892,44.6968574523926,90.2434472036548,0.010123942124967759
6-Oz,5,1.29468482919037,50.5580062866211,102.07717121742547,0.011479538818821283
6-Oz,5,1.44769088365138,55.980354309082,113.02495156207246,0.012836192501708903
6-Oz,5,1.60081603098661,60.8306655883789,122.81778342549221,0.01419390214141461
6-Oz,5,1.75376259721816,66.4630432128906,134.1896158486117,0.01555002836200102
6-Oz,5,1.90664944238961,71.7394180297852,144.84267468439867,0.016905625055854544
6-Oz,5,2.05959589220583,76.3059768676758,154.06260724517213,0.018261750244225026
6-Oz,5,2.21272115595639,81.2639846801758,164.07287959461448,0.01961946091614666
6-Oz,5,2.36584641970694,86.0748901367188,173.7861506681287,0.020977171588068205
6-Oz,5,2.51891184598207,90.9678726196289,183.6651361613531,0.022334351701041023
6-Oz,5,2.67179892398417,95.8939208984375,193.6108818604732,0.023689950459326307
6-Oz,5,2.82462616451085,99.9542999267578,201.808831813875,0.025045018658662876
6-Oz,5,2.97757261432707,104.483283996582,210.95290050431257,0.02640114384703336
6-Oz,5,3.13063827343285,108.934906005859,219.940774342931,0.027758326024437938
6-Oz,5,3.28382290899754,113.104034423828,228.35829051110855,0.02911656312644486
6-Oz,5,3.43682896345854,115.789772033691,233.7808243090762,0.030473216809332387
6-Oz,5,3.58971604146063,120.65779876709,243.60942386933363,0.03182881556761759
6-Oz,5,3.74272209592164,123.396430969238,249.13875243136974,0.033185469250505216
6-Oz,5,3.89560894109309,126.641906738281,255.69140373412245,0.03454106594435873
6-Oz,5,4.048733972013,123.225921630859,248.79449220027576,0.0358987745518486
6-Oz,5,4.08405251801014,8.69793224334717,17.56122094309452,0.03621193232635658